Workbook

Sheet HH Deposit Balance Comparison
A1: Household ID | B1: Household Name | C1: Officer Code | D1: Officer Name | E1: % of Deposits to Loans (Current) | F1: % of Deposits to Loans (Prior) | G1: % of Deposits to Loans (YTD) | H1: Current Month-end Deposit Balance | I1: Prior Month-end Deposit Balance | J1: Prior Year-end Deposit Balance | K1: Deposit Balance Change Month-over-Month | L1: Deposit Balance Change Year-to-date
A2: 1 | B2: MODERN BOOKKEEPING HOUSEHOLD | C2: Mark Morrison | D2: 615 | E2: =_xlfn.XLOOKUP(A2,'Current Month'!A:A,'Current Month'!I:I,"") -> 24.431643 | F2: =_xlfn.XLOOKUP(A2,'Prior Month'!A:A,'Prior Month'!I:I,"") -> 25.568844 | G2: =_xlfn.XLOOKUP(A2,'Year end 2024'!A:A,'Year end 2024'!I:I,"") -> 20.153983 | H2: =_xlfn.XLOOKUP(A2,'Current Month'!A:A,'Current Month'!E:E,0,0) -> 33327940 | I2: =_xlfn.XLOOKUP(A2,'Prior Month'!A:A,'Prior Month'!E:E,0,0) -> 34935884 | J2: =_xlfn.XLOOKUP(A2,'Year end 2024'!A:A,'Year end 2024'!E:E,0,0) -> 37995705 | K2: =IFERROR(SUM(H2-I2),H2) -> -1607943.4 | L2: =IFERROR(SUM(H2-J2),H2) -> -4667764.3
A3: 10 | B3: MARK CHERRY HOUSEHOLD | C3: Brad Kirkland | D3: 618 | E3: =_xlfn.XLOOKUP(A3,'Current Month'!A:A,'Current Month'!I:I,"") -> 0.13707749 | F3: =_xlfn.XLOOKUP(A3,'Prior Month'!A:A,'Prior Month'!I:I,"") -> 0.10933623 | G3: =_xlfn.XLOOKUP(A3,'Year end 2024'!A:A,'Year end 2024'!I:I,"") -> 0.031256665 | H3: =_xlfn.XLOOKUP(A3,'Current Month'!A:A,'Current Month'!E:E,0,0) -> 165289.76 | I3: =_xlfn.XLOOKUP(A3,'Prior Month'!A:A,'Prior Month'!E:E,0,0) -> 132546.61 | J3: =_xlfn.XLOOKUP(A3,'Year end 2024'!A:A,'Year end 2024'!E:E,0,0) -> 23095.28 | K3: =IFERROR(SUM(H3-I3),H3) -> 32743.15 | L3: =IFERROR(SUM(H3-J3),H3) -> 142194.48
A4: 100 | B4: Glenn A Bianchini Household | C4: Julie Jones | D4: 251 | E4: =_xlfn.XLOOKUP(A4,'Current Month'!A:A,'Current Month'!I:I,"") | F4: =_xlfn.XLOOKUP(A4,'Prior Month'!A:A,'Prior Month'!I:I,"") | G4: =_xlfn.XLOOKUP(A4,'Year end 2024'!A:A,'Year end 2024'!I:I,"") | H4: =_xlfn.XLOOKUP(A4,'Current Month'!A:A,'Current Month'!E:E,0,0) -> 22867.55 | I4: =_xlfn.XLOOKUP(A4,'Prior Month'!A:A,'Prior Month'!E:E,0,0) -> 23748.96 | J4: =_xlfn.XLOOKUP(A4,'Year end 2024'!A:A,'Year end 2024'!E:E,0,0) -> 28115.12 | K4: =IFERROR(SUM(H4-I4),H4) -> -881.41 | L4: =IFERROR(SUM(H4-J4),H4) -> -5247.57
A5: 1000 | B5: FUEL CELL ESA WCSU LLC HOUSEHOLD | C5: Mark Matheson | D5: 675 | E5: =_xlfn.XLOOKUP(A5,'Current Month'!A:A,'Current Month'!I:I,"") | F5: =_xlfn.XLOOKUP(A5,'Prior Month'!A:A,'Prior Month'!I:I,"") | G5: =_xlfn.XLOOKUP(A5,'Year end 2024'!A:A,'Year end 2024'!I:I,"") | H5: =_xlfn.XLOOKUP(A5,'Current Month'!A:A,'Current Month'!E:E,0,0) -> 0 | I5: =_xlfn.XLOOKUP(A5,'Prior Month'!A:A,'Prior Month'!E:E,0,0) -> 0 | J5: =_xlfn.XLOOKUP(A5,'Year end 2024'!A:A,'Year end 2024'!E:E,0,0) -> 0 | K5: =IFERROR(SUM(H5-I5),H5) -> 0 | L5: =IFERROR(SUM(H5-J5),H5) -> 0
A6: 1001 | B6: CENTRACORE LLC HOUSEHOLD | C6: Julie Jones | D6: 251 | E6: =_xlfn.XLOOKUP(A6,'Current Month'!A:A,'Current Month'!I:I,"") | F6: =_xlfn.XLOOKUP(A6,'Prior Month'!A:A,'Prior Month'!I:I,"") | G6: =_xlfn.XLOOKUP(A6,'Year end 2024'!A:A,'Year end 2024'!I:I,"") | H6: =_xlfn.XLOOKUP(A6,'Current Month'!A:A,'Current Month'!E:E,0,0) -> 220739.22 | I6: =_xlfn.XLOOKUP(A6,'Prior Month'!A:A,'Prior Month'!E:E,0,0) -> 220739.22 | J6: =_xlfn.XLOOKUP(A6,'Year end 2024'!A:A,'Year end 2024'!E:E,0,0) -> 15614.22 | K6: =IFERROR(SUM(H6-I6),H6) -> 0 | L6: =IFERROR(SUM(H6-J6),H6) -> 205125
A7: 1002 | B7: CONSTABLE REAL ESTATE LLC HOUSEHOLD | C7: Marlon Attiq | D7: 459 | E7: =_xlfn.XLOOKUP(A7,'Current Month'!A:A,'Current Month'!I:I,"") | F7: =_xlfn.XLOOKUP(A7,'Prior Month'!A:A,'Prior Month'!I:I,"") | G7: =_xlfn.XLOOKUP(A7,'Year end 2024'!A:A,'Year end 2024'!I:I,"") | H7: =_xlfn.XLOOKUP(A7,'Current Month'!A:A,'Current Month'!E:E,0,0) -> 20688.59 | I7: =_xlfn.XLOOKUP(A7,'Prior Month'!A:A,'Prior Month'!E:E,0,0) -> 32628.17 | J7: =_xlfn.XLOOKUP(A7,'Year end 2024'!A:A,'Year end 2024'!E:E,0,0) -> 32971.55 | K7: =IFERROR(SUM(H7-I7),H7) -> -11939.58 | L7: =IFERROR(SUM(H7-J7),H7) -> -12282.96
A8: 1003 | B8: ELISECO INC & NOVID LLC HOUSEHOLD | C8: Cary Listerman | D8: 130 | E8: =_xlfn.XLOOKUP(A8,'Current Month'!A:A,'Current Month'!I:I,"") | F8: =_xlfn.XLOOKUP(A8,'Prior Month'!A:A,'Prior Month'!I:I,"") | G8: =_xlfn.XLOOKUP(A8,'Year end 2024'!A:A,'Year end 2024'!I:I,"") -> 2.5914041 | H8: =_xlfn.XLOOKUP(A8,'Current Month'!A:A,'Current Month'!E:E,0,0) -> 728270.09 | I8: =_xlfn.XLOOKUP(A8,'Prior Month'!A:A,'Prior Month'!E:E,0,0) -> 728264.62 | J8: =_xlfn.XLOOKUP(A8,'Year end 2024'!A:A,'Year end 2024'!E:E,0,0) -> 1295702 | K8: =IFERROR(SUM(H8-I8),H8) -> 5.47 | L8: =IFERROR(SUM(H8-J8),H8) -> -567431.94
A9: 1007 | B9: KING CARPENTRY LLC HOUSEHOLD | C9: Julie Jones | D9: 251 | E9: =_xlfn.XLOOKUP(A9,'Current Month'!A:A,'Current Month'!I:I,"") | F9: =_xlfn.XLOOKUP(A9,'Prior Month'!A:A,'Prior Month'!I:I,"") | G9: =_xlfn.XLOOKUP(A9,'Year end 2024'!A:A,'Year end 2024'!I:I,"") | H9: =_xlfn.XLOOKUP(A9,'Current Month'!A:A,'Current Month'!E:E,0,0) -> 233578.99 | I9: =_xlfn.XLOOKUP(A9,'Prior Month'!A:A,'Prior Month'!E:E,0,0) -> 233583.99 | J9: =_xlfn.XLOOKUP(A9,'Year end 2024'!A:A,'Year end 2024'!E:E,0,0) -> 233698.99 | K9: =IFERROR(SUM(H9-I9),H9) -> -5 | L9: =IFERROR(SUM(H9-J9),H9) -> -120
A10: 1008 | B10: INTERVENTIONAL PAIN CENTER PLLC HOUSEHOLD | C10: Marlon Attiq | D10: 459 | E10: =_xlfn.XLOOKUP(A10,'Current Month'!A:A,'Current Month'!I:I,"") | F10: =_xlfn.XLOOKUP(A10,'Prior Month'!A:A,'Prior Month'!I:I,"") | G10: =_xlfn.XLOOKUP(A10,'Year end 2024'!A:A,'Year end 2024'!I:I,"") | H10: =_xlfn.XLOOKUP(A10,'Current Month'!A:A,'Current Month'!E:E,0,0) -> 5961.65 | I10: =_xlfn.XLOOKUP(A10,'Prior Month'!A:A,'Prior Month'!E:E,0,0) -> 5961.65 | J10: =_xlfn.XLOOKUP(A10,'Year end 2024'!A:A,'Year end 2024'!E:E,0,0) -> 6031.65 | K10: =IFERROR(SUM(H10-I10),H10) -> 0 | L10: =IFERROR(SUM(H10-J10),H10) -> -70
A11: 1009 | B11: INSPIRED CONCEPTS LLC HOUSEHOLD | C11: Joshua Copen | D11: 453 | E11: =_xlfn.XLOOKUP(A11,'Current Month'!A:A,'Current Month'!I:I,"") | F11: =_xlfn.XLOOKUP(A11,'Prior Month'!A:A,'Prior Month'!I:I,"") | G11: =_xlfn.XLOOKUP(A11,'Year end 2024'!A:A,'Year end 2024'!I:I,"") | H11: =_xlfn.XLOOKUP(A11,'Current Month'!A:A,'Current Month'!E:E,0,0) -> 57558.93 | I11: =_xlfn.XLOOKUP(A11,'Prior Month'!A:A,'Prior Month'!E:E,0,0) -> 45089.47 | J11: =_xlfn.XLOOKUP(A11,'Year end 2024'!A:A,'Year end 2024'!E:E,0,0) -> 57460.44 | K11: =IFERROR(SUM(H11-I11),H11) -> 12469.46 | L11: =IFERROR(SUM(H11-J11),H11) -> 98.49
A12: 101 | B12: Goodrich United Methodist Church Household | C12: Steve Tondreau | D12: 139 | E12: =_xlfn.XLOOKUP(A12,'Current Month'!A:A,'Current Month'!I:I,"") | F12: =_xlfn.XLOOKUP(A12,'Prior Month'!A:A,'Prior Month'!I:I,"") | G12: =_xlfn.XLOOKUP(A12,'Year end 2024'!A:A,'Year end 2024'!I:I,"") -> 11.556422 | H12: =_xlfn.XLOOKUP(A12,'Current Month'!A:A,'Current Month'!E:E,0,0) -> 152500.04 | I12: =_xlfn.XLOOKUP(A12,'Prior Month'!A:A,'Prior Month'!E:E,0,0) -> 181111.2 | J12: =_xlfn.XLOOKUP(A12,'Year end 2024'!A:A,'Year end 2024'!E:E,0,0) -> 142127 | K12: =IFERROR(SUM(H12-I12),H12) -> -28611.16 | L12: =IFERROR(SUM(H12-J12),H12) -> 10373.04
A13: 1010 | B13: THE GLAESER DAWES CORPORATION HOUSEHOLD | C13: Marlon Attiq | D13: 459 | E13: =_xlfn.XLOOKUP(A13,'Current Month'!A:A,'Current Month'!I:I,"") | F13: =_xlfn.XLOOKUP(A13,'Prior Month'!A:A,'Prior Month'!I:I,"") | G13: =_xlfn.XLOOKUP(A13,'Year end 2024'!A:A,'Year end 2024'!I:I,"") | H13: =_xlfn.XLOOKUP(A13,'Current Month'!A:A,'Current Month'!E:E,0,0) -> 2030.78 | I13: =_xlfn.XLOOKUP(A13,'Prior Month'!A:A,'Prior Month'!E:E,0,0) -> 2030.78 | J13: =_xlfn.XLOOKUP(A13,'Year end 2024'!A:A,'Year end 2024'!E:E,0,0) -> 2760.78 | K13: =IFERROR(SUM(H13-I13),H13) -> 0 | L13: =IFERROR(SUM(H13-J13),H13) -> -730
... A1083: 999 | B1083: WOODLINE BUILDING CO INC HOUSEHOLD | C1083: Jennifer Sherby | D1083: 151 | E1083: =_xlfn.XLOOKUP(A1083,'Current Month'!A:A,'Current Month'!I:I,"") | F1083: =_xlfn.XLOOKUP(A1083,'Prior Month'!A:A,'Prior Month'!I:I,"") | G1083: =_xlfn.XLOOKUP(A1083,'Year end 2024'!A:A,'Year end 2024'!I:I,"") | H1083: =_xlfn.XLOOKUP(A1083,'Current Month'!A:A,'Current Month'!E:E,0,0) -> 367433.88 | I1083: =_xlfn.XLOOKUP(A1083,'Prior Month'!A:A,'Prior Month'!E:E,0,0) -> 233391.48 | J1083: =_xlfn.XLOOKUP(A1083,'Year end 2024'!A:A,'Year end 2024'!E:E,0,0) -> 224438.35 | K1083: =IFERROR(SUM(H1083-I1083),H1083) -> 134042.4 | L1083: =IFERROR(SUM(H1083-J1083),H1083) -> 142995.53
A1084: Totals | E1084: =_xlfn.XLOOKUP(A1084,'Current Month'!A:A,'Current Month'!I:I,"") -> 0.87124073 | F1084: =_xlfn.XLOOKUP(A1084,'Prior Month'!A:A,'Prior Month'!I:I,"") -> 0.75685917 | G1084: =_xlfn.XLOOKUP(A1084,'Year end 2024'!A:A,'Year end 2024'!I:I,"") -> 0.75325652 | H1084: =SUM(H2:H1083) -> 5.6680562e+08 | I1084: =SUM(I2:I1083) -> 4.939073e+08 | J1084: =SUM(J2:J1083) -> 4.3826263e+08 | K1084: =SUM(K2:K1083) -> 72898324 | L1084: =SUM(L2:L1083) -> 1.2854299e+08

Sheet Current Month
A1: Household ID | B1: Household Name | C1: Officer Code | D1: Officer Name | E1: Current Balance - Deposit | F1: Current Balance - Loan | G1: Available Balance | H1: Lending Commitment | I1: Deposit to Loan Ratio
A2: 1 | B2: MODERN BOOKKEEPING HOUSEHOLD | C2: Mark Morrison | D2: 615 | E2: 33327940 | F2: 764130.12 | G2: 600000 | H2: =IF(ISBLANK(F2),"",(F2+G2)) -> 1364130.1 | I2: =IF(ISBLANK(F2), "", E2/H2) -> 24.431643
A3: 10 | B3: MARK CHERRY HOUSEHOLD | C3: Brad Kirkland | D3: 618 | E3: 165289.76 | F3: 855812.56 | G3: 350000 | H3: =IF(ISBLANK(F3),"",(F3+G3)) -> 1205812.6 | I3: =IF(ISBLANK(F3), "", E3/H3) -> 0.13707749
A4: 100 | B4: Glenn A Bianchini Household | C4: Julie Jones | D4: 251 | E4: 22867.55 | H4: =IF(ISBLANK(F4),"",(F4+G4)) | I4: =IF(ISBLANK(F4), "", E4/H4)
A5: 1000 | B5: FUEL CELL ESA WCSU LLC HOUSEHOLD | C5: Mark Matheson | D5: 675 | E5: 0 | H5: =IF(ISBLANK(F5),"",(F5+G5)) | I5: =IF(ISBLANK(F5), "", E5/H5)
A6: 1001 | B6: CENTRACORE LLC HOUSEHOLD | C6: Julie Jones | D6: 251 | E6: 220739.22 | H6: =IF(ISBLANK(F6),"",(F6+G6)) | I6: =IF(ISBLANK(F6), "", E6/H6)
A7: 1002 | B7: CONSTABLE REAL ESTATE LLC HOUSEHOLD | C7: Marlon Attiq | D7: 459 | E7: 20688.59 | H7: =IF(ISBLANK(F7),"",(F7+G7)) | I7: =IF(ISBLANK(F7), "", E7/H7)
A8: 1003 | B8: ELISECO INC & NOVID LLC HOUSEHOLD | C8: Cary Listerman | D8: 130 | E8: 728270.09 | H8: =IF(ISBLANK(F8),"",(F8+G8)) | I8: =IF(ISBLANK(F8), "", E8/H8)
A9: 1007 | B9: KING CARPENTRY LLC HOUSEHOLD | C9: Julie Jones | D9: 251 | E9: 233578.99 | H9: =IF(ISBLANK(F9),"",(F9+G9)) | I9: =IF(ISBLANK(F9), "", E9/H9)
A10: 1008 | B10: INTERVENTIONAL PAIN CENTER PLLC HOUSEHOLD | C10: Marlon Attiq | D10: 459 | E10: 5961.65 | H10: =IF(ISBLANK(F10),"",(F10+G10)) | I10: =IF(ISBLANK(F10), "", E10/H10)
A11: 1009 | B11: INSPIRED CONCEPTS LLC HOUSEHOLD | C11: Joshua Copen | D11: 453 | E11: 57558.93 | H11: =IF(ISBLANK(F11),"",(F11+G11)) | I11: =IF(ISBLANK(F11), "", E11/H11)
A12: 101 | B12: Goodrich United Methodist Church Household | C12: Steve Tondreau | D12: 139 | E12: 152500.04 | H12: =IF(ISBLANK(F12),"",(F12+G12)) | I12: =IF(ISBLANK(F12), "", E12/H12)
A13: 1010 | B13: THE GLAESER DAWES CORPORATION HOUSEHOLD | C13: Marlon Attiq | D13: 459 | E13: 2030.78 | H13: =IF(ISBLANK(F13),"",(F13+G13)) | I13: =IF(ISBLANK(F13), "", E13/H13)
A14: 1012 | B14: TIMOTHY P ISRAEL HOUSEHOLD | C14: Beth Arnold | D14: 162 | E14: 32535.81 | F14: 483293.21 | G14: 1776.3 | H14: =IF(ISBLANK(F14),"",(F14+G14)) -> 485069.51 | I14: =IF(ISBLANK(F14), "", E14/H14) -> 0.067074531
A15: 1013 | B15: JEREMY B STURZA HOUSEHOLD | C15: Julie Jones | D15: 251 | E15: 4004.87 | H15: =IF(ISBLANK(F15),"",(F15+G15)) | I15: =IF(ISBLANK(F15), "", E15/H15)
A16: 1014 | B16: DAVID M ROSE HOUSEHOLD | C16: Adrienne Flintoft | D16: 271 | E16: 8312.04 | F16: 40162.42 | G16: 39837.58 | H16: =IF(ISBLANK(F16),"",(F16+G16)) -> 80000 | I16: =IF(ISBLANK(F16), "", E16/H16) -> 0.1039005
A17: 1015 | B17: MARK GESUALE HOUSEHOLD | C17: Joshua Copen | D17: 453 | E17: 2043.06 | F17: 486220.48 | G17: 13779.52 | H17: =IF(ISBLANK(F17),"",(F17+G17)) -> 500000 | I17: =IF(ISBLANK(F17), "", E17/H17) -> 0.00408612
A18: 1016 | B18: SAMUEL D SWEET PLC HOUSEHOLD | C18: Julie Jones | D18: 251 | E18: 5006.72 | F18: 221649.57 | H18: =IF(ISBLANK(F18),"",(F18+G18)) -> 221649.57 | I18: =IF(ISBLANK(F18), "", E18/H18) -> 0.022588449
A19: 1017 | B19: RICHARD A BLASUTIG HOUSEHOLD | C19: Beth Arnold | D19: 162 | E19: 387.53 | F19: 52200.87 | H19: =IF(ISBLANK(F19),"",(F19+G19)) -> 52200.87 | I19: =IF(ISBLANK(F19), "", E19/H19) -> 0.0074238226
A20: 1018 | B20: DIANNE C KMIOTEK HOUSEHOLD | C20: Nicole Curtiss | D20: 475 | E20: 152109.17 | H20: =IF(ISBLANK(F20),"",(F20+G20)) | I20: =IF(ISBLANK(F20), "", E20/H20)
A21: 1020 | B21: CYPRESS RIDGE CONSULTING GROUP LLC HOUSEHOLD | C21: Cary Listerman | D21: 130 | E21: 186.9 | H21: =IF(ISBLANK(F21),"",(F21+G21)) | I21: =IF(ISBLANK(F21), "", E21/H21)
A22: 1024 | B22: LEON D HIEBER JR HOUSEHOLD | C22: Vladislav Peck | D22: 460 | E22: 109473.77 | H22: =IF(ISBLANK(F22),"",(F22+G22)) | I22: =IF(ISBLANK(F22), "", E22/H22)
A23: 103 | B23: FRIENDS OF THE CLARKSTON INDEPENDENCE HOUSEHOLD | C23: Jennifer Sherby | D23: 151 | E23: 65065.61 | H23: =IF(ISBLANK(F23),"",(F23+G23)) | I23: =IF(ISBLANK(F23), "", E23/H23)
A24: 1030 | B24: STUDENT ADVOCACY CENTER OF MICHIGAN INC HOUSEHOLD | C24: Cary Listerman | D24: 130 | E24: 185197.59 | H24: =IF(ISBLANK(F24),"",(F24+G24)) | I24: =IF(ISBLANK(F24), "", E24/H24)
A25: 1032 | B25: MICHELE SHAUGHNESSY HOUSEHOLD | C25: Cary Listerman | D25: 130 | E25: 305229.83 | H25: =IF(ISBLANK(F25),"",(F25+G25)) | I25: =IF(ISBLANK(F25), "", E25/H25)
A26: 1034 | B26: EICHNER REALTY INC HOUSEHOLD | C26: Vladislav Peck | D26: 460 | E26: 26271.27 | H26: =IF(ISBLANK(F26),"",(F26+G26)) | I26: =IF(ISBLANK(F26), "", E26/H26)
A27: 1035 | B27: TMT MANAGEMENT INC HOUSEHOLD | C27: Marlon Attiq | D27: 459 | E27: 858 | H27: =IF(ISBLANK(F27),"",(F27+G27)) | I27: =IF(ISBLANK(F27), "", E27/H27)
A28: 1037 | B28: SUNSHINE FOODS AND WINE LLC HOUSEHOLD | C28: Vladislav Peck | D28: 460 | E28: 3773.67 | H28: =IF(ISBLANK(F28),"",(F28+G28)) | I28: =IF(ISBLANK(F28), "", E28/H28)
A29: 1039 | B29: TEKSOFT SYSTEMS INC HOUSEHOLD | C29: Julie Jones | D29: 251 | E29: 2084.15 | H29: =IF(ISBLANK(F29),"",(F29+G29)) | I29: =IF(ISBLANK(F29), "", E29/H29)
A30: 104 | B30: Independence Dental PC Household | C30: Marlon Attiq | D30: 459 | E30: 2738.09 | F30: 40014.85 | H30: =IF(ISBLANK(F30),"",(F30+G30)) -> 40014.85 | I30: =IF(ISBLANK(F30), "", E30/H30) -> 0.068426847
A31: 1040 | B31: SANDBEAR EXPRESS INC HOUSEHOLD | C31: Marlon Attiq | D31: 459 | E31: 8.03 | H31: =IF(ISBLANK(F31),"",(F31+G31)) | I31: =IF(ISBLANK(F31), "", E31/H31)
A32: 1043 | B32: CSV RESTAURANTS LLC HOUSEHOLD | C32: Julie Jones | D32: 251 | E32: 227.52 | H32: =IF(ISBLANK(F32),"",(F32+G32)) | I32: =IF(ISBLANK(F32), "", E32/H32)
A33: 1044 | B33: STRATEGIC SERVICES GROUP INC HOUSEHOLD | C33: Joshua Copen | D33: 453 | E33: 267819.74 | H33: =IF(ISBLANK(F33),"",(F33+G33)) | I33: =IF(ISBLANK(F33), "", E33/H33)
A34: 1045 | B34: PAINT CREEK MGMT LLC HOUSEHOLD | C34: Thomas Merrill | D34: 640 | E34: 2141560.4 | F34: 1713695.1 | H34: =IF(ISBLANK(F34),"",(F34+G34)) -> 1713695.1 | I34: =IF(ISBLANK(F34), "", E34/H34) -> 1.2496741
A35: 1046 | B35: MORTGAGE RESOURCE PLUS, INC HOUSEHOLD | C35: Thomas Merrill | D35: 640 | E35: 632211.49 | H35: =IF(ISBLANK(F35),"",(F35+G35)) | I35: =IF(ISBLANK(F35), "", E35/H35)
A36: 1047 | B36: LOVE INC OF NORTH OAKLAND COUNTY HOUSEHOLD | C36: Marlon Attiq | D36: 459 | E36: 37346.59 | H36: =IF(ISBLANK(F36),"",(F36+G36)) | I36: =IF(ISBLANK(F36), "", E36/H36)
A37: 105 | B37: CONSOLIDATED MEDICAL BILLING LLC HOUSEHOLD | C37: Taylor Spicer | D37: 467 | E37: 110593.52 | H37: =IF(ISBLANK(F37),"",(F37+G37)) | I37: =IF(ISBLANK(F37), "", E37/H37)
A38: 1050 | B38: MICHIGAN STRATEGIC FUND HOUSEHOLD | C38: Cary Listerman | D38: 130 | E38: 7773376.3 | H38: =IF(ISBLANK(F38),"",(F38+G38)) | I38: =IF(ISBLANK(F38), "", E38/H38)
A39: 1052 | B39: MRA PROPERTIES LLC HOUSEHOLD | C39: Brad Kirkland | D39: 618 | E39: 342320.23 | F39: 0 | G39: 100000 | H39: =IF(ISBLANK(F39),"",(F39+G39)) -> 100000 | I39: =IF(ISBLANK(F39), "", E39/H39) -> 3.4232023
A40: 1053 | B40: DALE WELSH HOUSEHOLD | C40: Julie Jones | D40: 251 | E40: 340.72 | H40: =IF(ISBLANK(F40),"",(F40+G40)) | I40: =IF(ISBLANK(F40), "", E40/H40)
...

Sheet Prior Month
A1: Household ID | B1: Household Name | C1: Officer Code | D1: Officer Name | E1: Current Balance - Deposit | F1: Current Balance - Loan | G1: Available Balance | H1: Total Lending | I1: Ratio
A2: 1 | B2: MODERN BOOKKEEPING HOUSEHOLD | C2: Mark Morrison | D2: 615 | E2: 34935884 | F2: 766345.83 | G2: 600000 | H2: =IF(ISBLANK(F2), "",(F2+G2)) -> 1366345.8 | I2: =IF(ISBLANK(F2), "", E2/H2) -> 25.568844
A3: 10 | B3: MARK CHERRY HOUSEHOLD | C3: Brad Kirkland | D3: 618 | E3: 132546.61 | F3: 862284.42 | G3: 350000 | H3: =IF(ISBLANK(F3), "",(F3+G3)) -> 1212284.4 | I3: =IF(ISBLANK(F3), "", E3/H3) -> 0.10933623
A4: 100 | B4: Glenn A Bianchini Household | C4: Julie Jones | D4: 251 | E4: 23748.96 | H4: =IF(ISBLANK(F4), "",(F4+G4)) | I4: =IF(ISBLANK(F4), "", E4/H4)
A5: 1000 | B5: FUEL CELL ESA WCSU LLC HOUSEHOLD | C5: Mark Matheson | D5: 675 | E5: 0 | H5: =IF(ISBLANK(F5), "",(F5+G5)) | I5: =IF(ISBLANK(F5), "", E5/H5)
A6: 1001 | B6: CENTRACORE LLC HOUSEHOLD | C6: Julie Jones | D6: 251 | E6: 220739.22 | H6: =IF(ISBLANK(F6), "",(F6+G6)) | I6: =IF(ISBLANK(F6), "", E6/H6)
A7: 1002 | B7: CONSTABLE REAL ESTATE LLC HOUSEHOLD | C7: Marlon Attiq | D7: 459 | E7: 32628.17 | H7: =IF(ISBLANK(F7), "",(F7+G7)) | I7: =IF(ISBLANK(F7), "", E7/H7)
A8: 1003 | B8: ELISECO INC & NOVID LLC HOUSEHOLD | C8: Cary Listerman | D8: 130 | E8: 728264.62 | H8: =IF(ISBLANK(F8), "",(F8+G8)) | I8: =IF(ISBLANK(F8), "", E8/H8)
A9: 1007 | B9: KING CARPENTRY LLC HOUSEHOLD | C9: Julie Jones | D9: 251 | E9: 233583.99 | H9: =IF(ISBLANK(F9), "",(F9+G9)) | I9: =IF(ISBLANK(F9), "", E9/H9)
A10: 1008 | B10: INTERVENTIONAL PAIN CENTER PLLC HOUSEHOLD | C10: Marlon Attiq | D10: 459 | E10: 5961.65 | H10: =IF(ISBLANK(F10), "",(F10+G10)) | I10: =IF(ISBLANK(F10), "", E10/H10)
A11: 1009 | B11: INSPIRED CONCEPTS LLC HOUSEHOLD | C11: Joshua Copen | D11: 453 | E11: 45089.47 | H11: =IF(ISBLANK(F11), "",(F11+G11)) | I11: =IF(ISBLANK(F11), "", E11/H11)
A12: 101 | B12: Goodrich United Methodist Church Household | C12: Steve Tondreau | D12: 139 | E12: 181111.2 | H12: =IF(ISBLANK(F12), "",(F12+G12)) | I12: =IF(ISBLANK(F12), "", E12/H12)
A13: 1010 | B13: THE GLAESER DAWES CORPORATION HOUSEHOLD | C13: Marlon Attiq | D13: 459 | E13: 2030.78 | H13: =IF(ISBLANK(F13), "",(F13+G13)) | I13: =IF(ISBLANK(F13), "", E13/H13)
A14: 1012 | B14: TIMOTHY P ISRAEL HOUSEHOLD | C14: Beth Arnold | D14: 162 | E14: 35284.8 | F14: 485089.91 | G14: 792.07 | H14: =IF(ISBLANK(F14), "",(F14+G14)) -> 485881.98 | I14: =IF(ISBLANK(F14), "", E14/H14) -> 0.072620104
A15: 1013 | B15: JEREMY B STURZA HOUSEHOLD | C15: Julie Jones | D15: 251 | E15: 3565.5 | H15: =IF(ISBLANK(F15), "",(F15+G15)) | I15: =IF(ISBLANK(F15), "", E15/H15)
A16: 1014 | B16: DAVID M ROSE HOUSEHOLD | C16: Adrienne Flintoft | D16: 271 | E16: 11513.41 | F16: 336101.06 | G16: 30023.39 | H16: =IF(ISBLANK(F16), "",(F16+G16)) -> 366124.45 | I16: =IF(ISBLANK(F16), "", E16/H16) -> 0.031446712
A17: 1015 | B17: MARK GESUALE HOUSEHOLD | C17: Joshua Copen | D17: 453 | E17: 1277.31 | F17: 482761.36 | G17: 17238.64 | H17: =IF(ISBLANK(F17), "",(F17+G17)) -> 500000 | I17: =IF(ISBLANK(F17), "", E17/H17) -> 0.00255462
A18: 1016 | B18: SAMUEL D SWEET PLC HOUSEHOLD | C18: Julie Jones | D18: 251 | E18: 8144.99 | F18: 222662.45 | H18: =IF(ISBLANK(F18), "",(F18+G18)) -> 222662.45 | I18: =IF(ISBLANK(F18), "", E18/H18) -> 0.036579989
A19: 1017 | B19: RICHARD A BLASUTIG HOUSEHOLD | C19: Beth Arnold | D19: 162 | E19: 336.65 | F19: 53824.25 | H19: =IF(ISBLANK(F19), "",(F19+G19)) -> 53824.25 | I19: =IF(ISBLANK(F19), "", E19/H19) -> 0.0062546157
A20: 1018 | B20: DIANNE C KMIOTEK HOUSEHOLD | C20: Nicole Curtiss | D20: 475 | E20: 147015.11 | H20: =IF(ISBLANK(F20), "",(F20+G20)) | I20: =IF(ISBLANK(F20), "", E20/H20)
A21: 1020 | B21: CYPRESS RIDGE CONSULTING GROUP LLC HOUSEHOLD | C21: Cary Listerman | D21: 130 | E21: 196.9 | H21: =IF(ISBLANK(F21), "",(F21+G21)) | I21: =IF(ISBLANK(F21), "", E21/H21)
A22: 1024 | B22: LEON D HIEBER JR HOUSEHOLD | C22: Vladislav Peck | D22: 460 | E22: 109106.1 | H22: =IF(ISBLANK(F22), "",(F22+G22)) | I22: =IF(ISBLANK(F22), "", E22/H22)
A23: 103 | B23: FRIENDS OF THE CLARKSTON INDEPENDENCE HOUSEHOLD | C23: Jennifer Sherby | D23: 151 | E23: 66169.49 | H23: =IF(ISBLANK(F23), "",(F23+G23)) | I23: =IF(ISBLANK(F23), "", E23/H23)
A24: 1030 | B24: STUDENT ADVOCACY CENTER OF MICHIGAN INC HOUSEHOLD | C24: Cary Listerman | D24: 130 | E24: 184605.58 | H24: =IF(ISBLANK(F24), "",(F24+G24)) | I24: =IF(ISBLANK(F24), "", E24/H24)
A25: 1032 | B25: MICHELE SHAUGHNESSY HOUSEHOLD | C25: Cary Listerman | D25: 130 | E25: 304204.7 | H25: =IF(ISBLANK(F25), "",(F25+G25)) | I25: =IF(ISBLANK(F25), "", E25/H25)
A26: 1034 | B26: EICHNER REALTY INC HOUSEHOLD | C26: Vladislav Peck | D26: 460 | E26: 70705.06 | H26: =IF(ISBLANK(F26), "",(F26+G26)) | I26: =IF(ISBLANK(F26), "", E26/H26)
A27: 1035 | B27: TMT MANAGEMENT INC HOUSEHOLD | C27: Marlon Attiq | D27: 459 | E27: 858 | H27: =IF(ISBLANK(F27), "",(F27+G27)) | I27: =IF(ISBLANK(F27), "", E27/H27)
A28: 1037 | B28: SUNSHINE FOODS AND WINE LLC HOUSEHOLD | C28: Vladislav Peck | D28: 460 | E28: 3803.67 | H28: =IF(ISBLANK(F28), "",(F28+G28)) | I28: =IF(ISBLANK(F28), "", E28/H28)
A29: 1039 | B29: TEKSOFT SYSTEMS INC HOUSEHOLD | C29: Julie Jones | D29: 251 | E29: 2089.15 | H29: =IF(ISBLANK(F29), "",(F29+G29)) | I29: =IF(ISBLANK(F29), "", E29/H29)
A30: 104 | B30: Independence Dental PC Household | C30: Marlon Attiq | D30: 459 | E30: 2744.88 | F30: 42743.89 | H30: =IF(ISBLANK(F30), "",(F30+G30)) -> 42743.89 | I30: =IF(ISBLANK(F30), "", E30/H30) -> 0.064216897
A31: 1040 | B31: SANDBEAR EXPRESS INC HOUSEHOLD | C31: Marlon Attiq | D31: 459 | E31: 8.03 | H31: =IF(ISBLANK(F31), "",(F31+G31)) | I31: =IF(ISBLANK(F31), "", E31/H31)
A32: 1043 | B32: CSV RESTAURANTS LLC HOUSEHOLD | C32: Julie Jones | D32: 251 | E32: 776.89 | H32: =IF(ISBLANK(F32), "",(F32+G32)) | I32: =IF(ISBLANK(F32), "", E32/H32)
A33: 1044 | B33: STRATEGIC SERVICES GROUP INC HOUSEHOLD | C33: Joshua Copen | D33: 453 | E33: 162676.32 | H33: =IF(ISBLANK(F33), "",(F33+G33)) | I33: =IF(ISBLANK(F33), "", E33/H33)
A34: 1045 | B34: PAINT CREEK MGMT LLC HOUSEHOLD | C34: Thomas Merrill | D34: 640 | E34: 2115363 | F34: 1720950.9 | H34: =IF(ISBLANK(F34), "",(F34+G34)) -> 1720950.9 | I34: =IF(ISBLANK(F34), "", E34/H34) -> 1.2291827
A35: 1046 | B35: MORTGAGE RESOURCE PLUS, INC HOUSEHOLD | C35: Thomas Merrill | D35: 640 | E35: 583650.25 | H35: =IF(ISBLANK(F35), "",(F35+G35)) | I35: =IF(ISBLANK(F35), "", E35/H35)
A36: 1047 | B36: LOVE INC OF NORTH OAKLAND COUNTY HOUSEHOLD | C36: Marlon Attiq | D36: 459 | E36: 37653.84 | H36: =IF(ISBLANK(F36), "",(F36+G36)) | I36: =IF(ISBLANK(F36), "", E36/H36)
A37: 105 | B37: CONSOLIDATED MEDICAL BILLING LLC HOUSEHOLD | C37: Taylor Spicer | D37: 467 | E37: 87576.48 | H37: =IF(ISBLANK(F37), "",(F37+G37)) | I37: =IF(ISBLANK(F37), "", E37/H37)
A38: 1050 | B38: MICHIGAN STRATEGIC FUND HOUSEHOLD | C38: Cary Listerman | D38: 130 | E38: 7765155 | H38: =IF(ISBLANK(F38), "",(F38+G38)) | I38: =IF(ISBLANK(F38), "", E38/H38)
A39: 1052 | B39: MRA PROPERTIES LLC HOUSEHOLD | C39: Brad Kirkland | D39: 618 | E39: 212050.34 | F39: 0 | G39: 100000 | H39: =IF(ISBLANK(F39), "",(F39+G39)) -> 100000 | I39: =IF(ISBLANK(F39), "", E39/H39) -> 2.1205034
A40: 1053 | B40: DALE WELSH HOUSEHOLD | C40: Julie Jones | D40: 251 | E40: 340.65 | H40: =IF(ISBLANK(F40), "",(F40+G40)) | I40: =IF(ISBLANK(F40), "", E40/H40)
...

Sheet Year end 2024
A1: Household ID | B1: Household Name | C1: Officer Code | D1: Officer Name | E1: Current Balance - Deposit | F1: Current Balance - Loan | G1: Available Balance | H1: Total Lending | I1: Ratio
A2: 1 | B2: MODERN BOOKKEEPING HOUSEHOLD | C2: Mark Morrison | D2: 615 | E2: 37995705 | F2: 785270.23 | G2: 1100000 | H2: =IF(ISBLANK(F2), "",(F2+G2)) -> 1885270.2 | I2: =IF(ISBLANK(F2), "", E2/H2) -> 20.153983
A3: 10 | B3: MARK CHERRY HOUSEHOLD | C3: Brad Kirkland | D3: 618 | E3: 23095.28 | F3: 577059.56 | G3: 161831.81 | H3: =IF(ISBLANK(F3), "",(F3+G3)) -> 738891.37 | I3: =IF(ISBLANK(F3), "", E3/H3) -> 0.031256665
A4: 100 | B4: Glenn A Bianchini Household | C4: Julie Jones | D4: 251 | E4: 28115.12 | H4: =IF(ISBLANK(F4), "",(F4+G4)) | I4: =IF(ISBLANK(F4), "", E4/H4)
A5: 1000 | B5: FUEL CELL ESA WCSU LLC HOUSEHOLD | C5: Mark Matheson | D5: 675 | E5: 0 | H5: =IF(ISBLANK(F5), "",(F5+G5)) | I5: =IF(ISBLANK(F5), "", E5/H5)
A6: 1001 | B6: CENTRACORE LLC HOUSEHOLD | C6: Julie Jones | D6: 251 | E6: 15614.22 | H6: =IF(ISBLANK(F6), "",(F6+G6)) | I6: =IF(ISBLANK(F6), "", E6/H6)
A7: 1002 | B7: CONSTABLE REAL ESTATE LLC HOUSEHOLD | C7: Marlon Attiq | D7: 459 | E7: 32971.55 | H7: =IF(ISBLANK(F7), "",(F7+G7)) | I7: =IF(ISBLANK(F7), "", E7/H7)
A8: 1003 | B8: ELISECO INC & NOVID LLC HOUSEHOLD | C8: Cary Listerman | D8: 130 | E8: 1295702 | F8: 0 | G8: 500000 | H8: =IF(ISBLANK(F8), "",(F8+G8)) -> 500000 | I8: =IF(ISBLANK(F8), "", E8/H8) -> 2.5914041
A9: 1004 | B9: SABRENY LP HOUSEHOLD | C9: Jose Morales | D9: 631 | E9: 5208.73 | H9: =IF(ISBLANK(F9), "",(F9+G9)) | I9: =IF(ISBLANK(F9), "", E9/H9)
A10: 1005 | B10: RONALD L NEWTON HOUSEHOLD | C10: FEM-Sam Bazido | D10: 436 | E10: 3710.58 | H10: =IF(ISBLANK(F10), "",(F10+G10)) | I10: =IF(ISBLANK(F10), "", E10/H10)
A11: 1006 | B11: CENTROIS LLC HOUSEHOLD | C11: Marlon Attiq | D11: 459 | E11: 594.72 | H11: =IF(ISBLANK(F11), "",(F11+G11)) | I11: =IF(ISBLANK(F11), "", E11/H11)
A12: 1007 | B12: KING CARPENTRY LLC HOUSEHOLD | C12: Julie Jones | D12: 251 | E12: 233698.99 | H12: =IF(ISBLANK(F12), "",(F12+G12)) | I12: =IF(ISBLANK(F12), "", E12/H12)
A13: 1008 | B13: INTERVENTIONAL PAIN CENTER PLLC HOUSEHOLD | C13: Marlon Attiq | D13: 459 | E13: 6031.65 | H13: =IF(ISBLANK(F13), "",(F13+G13)) | I13: =IF(ISBLANK(F13), "", E13/H13)
A14: 1009 | B14: INSPIRED CONCEPTS LLC HOUSEHOLD | C14: FEM-Sam Bazido | D14: 436 | E14: 57460.44 | H14: =IF(ISBLANK(F14), "",(F14+G14)) | I14: =IF(ISBLANK(F14), "", E14/H14)
A15: 101 | B15: Goodrich United Methodist Church Household | C15: Steve Tondreau | D15: 139 | E15: 142127 | F15: 12298.53 | H15: =IF(ISBLANK(F15), "",(F15+G15)) -> 12298.53 | I15: =IF(ISBLANK(F15), "", E15/H15) -> 11.556422
A16: 1010 | B16: THE GLAESER DAWES CORPORATION HOUSEHOLD | C16: Marlon Attiq | D16: 459 | E16: 2760.78 | H16: =IF(ISBLANK(F16), "",(F16+G16)) | I16: =IF(ISBLANK(F16), "", E16/H16)
A17: 1011 | B17: MAKOMI INC HOUSEHOLD | C17: Julie Jones | D17: 251 | E17: 847.49 | H17: =IF(ISBLANK(F17), "",(F17+G17)) | I17: =IF(ISBLANK(F17), "", E17/H17)
A18: 1012 | B18: TIMOTHY P ISRAEL HOUSEHOLD | C18: Beth Arnold | D18: 162 | E18: 337.61 | F18: 493672.27 | G18: 0 | H18: =IF(ISBLANK(F18), "",(F18+G18)) -> 493672.27 | I18: =IF(ISBLANK(F18), "", E18/H18) -> 0.00068387475
A19: 1013 | B19: JEREMY B STURZA HOUSEHOLD | C19: Julie Jones | D19: 251 | E19: 4004.73 | H19: =IF(ISBLANK(F19), "",(F19+G19)) | I19: =IF(ISBLANK(F19), "", E19/H19)
A20: 1014 | B20: DAVID M ROSE HOUSEHOLD | C20: Adrienne Flintoft | D20: 271 | E20: 25899.68 | F20: 288722.31 | G20: 80000 | H20: =IF(ISBLANK(F20), "",(F20+G20)) -> 368722.31 | I20: =IF(ISBLANK(F20), "", E20/H20) -> 0.070241695
A21: 1015 | B21: MARK GESUALE HOUSEHOLD | C21: FEM-Sam Bazido | D21: 436 | E21: 19355.47 | F21: 379220.48 | G21: 120779.52 | H21: =IF(ISBLANK(F21), "",(F21+G21)) -> 500000 | I21: =IF(ISBLANK(F21), "", E21/H21) -> 0.03871094
A22: 1016 | B22: SAMUEL D SWEET PLC HOUSEHOLD | C22: Julie Jones | D22: 251 | E22: 30283.69 | F22: 231707.81 | H22: =IF(ISBLANK(F22), "",(F22+G22)) -> 231707.81 | I22: =IF(ISBLANK(F22), "", E22/H22) -> 0.13069775
A23: 1017 | B23: RICHARD A BLASUTIG HOUSEHOLD | C23: Beth Arnold | D23: 162 | E23: 1413.21 | F23: 181928.67 | H23: =IF(ISBLANK(F23), "",(F23+G23)) -> 181928.67 | I23: =IF(ISBLANK(F23), "", E23/H23) -> 0.0077679345
A24: 1018 | B24: DIANNE C KMIOTEK HOUSEHOLD | C24: FEM-Alecia Campbell | D24: 115 | E24: 188654.98 | H24: =IF(ISBLANK(F24), "",(F24+G24)) | I24: =IF(ISBLANK(F24), "", E24/H24)
A25: 1019 | B25: TIDY MRO ENTERPRISES LLC HOUSEHOLD | C25: Vladislav Peck | D25: 460 | E25: 396.82 | H25: =IF(ISBLANK(F25), "",(F25+G25)) | I25: =IF(ISBLANK(F25), "", E25/H25)
A26: 1020 | B26: CYPRESS RIDGE CONSULTING GROUP LLC HOUSEHOLD | C26: Cary Listerman | D26: 130 | E26: 286.9 | H26: =IF(ISBLANK(F26), "",(F26+G26)) | I26: =IF(ISBLANK(F26), "", E26/H26)
A27: 1024 | B27: LEON D HIEBER JR HOUSEHOLD | C27: Vladislav Peck | D27: 460 | E27: 105804.73 | H27: =IF(ISBLANK(F27), "",(F27+G27)) | I27: =IF(ISBLANK(F27), "", E27/H27)
A28: 1028 | B28: EDWARD D ROOS HOUSEHOLD | C28: Cary Listerman | D28: 130 | E28: 649899.15 | H28: =IF(ISBLANK(F28), "",(F28+G28)) | I28: =IF(ISBLANK(F28), "", E28/H28)
A29: 1029 | B29: SAVARINO PROPERTIES HOUSEHOLD | C29: Vladislav Peck | D29: 460 | E29: 1783.84 | H29: =IF(ISBLANK(F29), "",(F29+G29)) | I29: =IF(ISBLANK(F29), "", E29/H29)
A30: 103 | B30: FRIENDS OF THE CLARKSTON INDEPENDENCE HOUSEHOLD | C30: Jennifer Sherby | D30: 151 | E30: 61127.35 | H30: =IF(ISBLANK(F30), "",(F30+G30)) | I30: =IF(ISBLANK(F30), "", E30/H30)
A31: 1030 | B31: STUDENT ADVOCACY CENTER OF MICHIGAN INC HOUSEHOLD | C31: Cary Listerman | D31: 130 | E31: 269810.04 | H31: =IF(ISBLANK(F31), "",(F31+G31)) | I31: =IF(ISBLANK(F31), "", E31/H31)
A32: 1032 | B32: MICHELE SHAUGHNESSY HOUSEHOLD | C32: Cary Listerman | D32: 130 | E32: 295000 | H32: =IF(ISBLANK(F32), "",(F32+G32)) | I32: =IF(ISBLANK(F32), "", E32/H32)
A33: 1033 | B33: CANCER SUPPORT COMMUNITY HOUSEHOLD | C33: Vladislav Peck | D33: 460 | E33: 53993.86 | H33: =IF(ISBLANK(F33), "",(F33+G33)) | I33: =IF(ISBLANK(F33), "", E33/H33)
A34: 1034 | B34: EICHNER REALTY INC HOUSEHOLD | C34: Vladislav Peck | D34: 460 | E34: 19534.27 | H34: =IF(ISBLANK(F34), "",(F34+G34)) | I34: =IF(ISBLANK(F34), "", E34/H34)
A35: 1035 | B35: TMT MANAGEMENT INC HOUSEHOLD | C35: Marlon Attiq | D35: 459 | E35: 1373 | H35: =IF(ISBLANK(F35), "",(F35+G35)) | I35: =IF(ISBLANK(F35), "", E35/H35)
... A37: 1039 | B37: TEKSOFT SYSTEMS INC HOUSEHOLD | C37: Julie Jones | D37: 251 | E37: 316.73 | H37: =IF(ISBLANK(F37), "",(F37+G37)) | I37: =IF(ISBLANK(F37), "", E37/H37)
A38: 104 | B38: Independence Dental PC Household | C38: Marlon Attiq | D38: 459 | E38: 2451.12 | F38: 55340.32 | H38: =IF(ISBLANK(F38), "",(F38+G38)) -> 55340.32 | I38: =IF(ISBLANK(F38), "", E38/H38) -> 0.044291757
A39: 1040 | B39: SANDBEAR EXPRESS INC HOUSEHOLD | C39: Marlon Attiq | D39: 459 | E39: 18.03 | H39: =IF(ISBLANK(F39), "",(F39+G39)) | I39: =IF(ISBLANK(F39), "", E39/H39)
A40: 1041 | B40: JDI TRAVEL INC HOUSEHOLD | C40: FEM-Sam Bazido | D40: 436 | E40: 99.18 | H40: =IF(ISBLANK(F40), "",(F40+G40)) | I40: =IF(ISBLANK(F40), "", E40/H40)
A41: 1042 | B41: FINNEA GROUP LLC HOUSEHOLD | C41: Marlon Attiq | D41: 459 | E41: 3.85 | H41: =IF(ISBLANK(F41), "",(F41+G41)) | I41: =IF(ISBLANK(F41), "", E41/H41)
...
